Workbook
Name LoteElectro: Criterios!$B$26:$B$27
Name LoteTACEco: Criterios!$B$22:$B$24

Sheet LOTES (TAC Y ECO)
A1: SERVICIO DE PRUEBAS DIAGNÓSTICAS PARA FRATERNIDAD-MUPRESPA EN LA COMUNIDAD AUTÓNOMA DE CASTILLA Y LEÓN LOTES TAC Y ECOGRAFÍA
A2: IMPORTES OFERTADOS: A cumplimentar para TODOS LOS SERVICIOS OFERTADOS, tanto obligatorios como valorables. SERVICIOS OBLIGATORIOS: De no cumplimentarse, la OFERTA SERÁ EXCLUIDA. Corresponden a las casillas sobre fondo amarillo. RESTO DE CAMPOS: De no cumplimentarse, no serán considerados en la valoración de la oferta. Hay campos desplegables que validan los datos introducidos, NO debe hacerse "copiar y pegar" de datos, ya que el formato de los datos debe validarse.
A3: Número lote
A4: Lote: Localidad (Provincia) - Pruebas diagnósticas | B4: =IFERROR(VLOOKUP(B3,Criterios!B22:N35,2,FALSE),"")
A5: Razón social
A6: CIF
A7: Domicilio social
A8: Localidad | C8: Provincia
A9: Representación de la empresa
A10: Nombre y apellidos del representante de la empresa
A11: DNI del representante de la empresa
A12: =IF(B11<>"",CONCATENATE("Don/Dña. ",B10, ", con DNI nº ",B11,", en nombre propio/en representación de la empresa ",B5,", con domicilio social en ",B7," y con CIF nº ",B6,", declara que adscribirá a la ejecución del servicio los siguientes centros y equipos:"),"")
A13: Datos del centro
A14: Nombre del centro asistencial
A15: Dirección asistencial
A16: Localidad | C16: Provincia | D16: =IFERROR(VLOOKUP(B3,Criterios!B22:N35,13,FALSE),"Elija nº de lote") -> Elija nº de lote
A17: Teléfono | C17: Fax
A18: Horario de citación
A19: Horario de realización de pruebas
A20: Correo electrónico a efectos de notificaciones
A21: Página web
A22: Personas de contacto (citación, incidencias, aspectos administrativos,…)
A23: Nombre y apellidos
A24: Correo electrónico a efectos de notificaciones
A25: Teléfono
A26: Interlocutor médico
A27: Nombre y apellidos
A28: Correo electrónico a efectos de notificaciones
A29: Teléfono
... A36: OBLIGATORIO
A37: EQUIPAMIENTO | B37: Disponibilidad | C37: Marca y modelo | D37: Características específicas | F37: Puntuación máxima | G37: Puntuación obt. Caract.
A38: Tomografía axial computarizada (TAC) | F38: 5 | G38: =IFERROR(IF($B38="Si",VLOOKUP($D38,Criterios!$Q$12:$R$14,2,FALSE),0),0) -> 0
A39: Ecógrafo | F39: 5 | G39: =IFERROR(IF($B39="Si",VLOOKUP($D39,Criterios!$Q$16:$R$18,2,FALSE),0),0) -> 0
A40: Electromiógrafo
A41: UNIDADES ASISTENCIALES | B41: Disponibilidad
A42: Radiodiagnóstico (U.88)
A43: Neurología (U.17)
A44: Neurofisiología (U.18)
A46: VALORABLE
A47: EQUIPAMIENTO | B47: Disponibilidad | C47: Marca y modelo | D47: Características específicas | F47: Puntuación máxima | G47: Puntuación obtenida
...

Sheet LOTE (TAC)
A1: SERVICIO DE PRUEBAS DIAGNÓSTICAS PARA FRATERNIDAD-MUPRESPA EN LA COMUNIDAD AUTÓNOMA DE CASTILLA Y LEÓN LOTE TAC
A2: IMPORTES OFERTADOS: A cumplimentar para TODOS LOS SERVICIOS OFERTADOS, tanto obligatorios como valorables. SERVICIOS OBLIGATORIOS: De no cumplimentarse, la OFERTA SERÁ EXCLUIDA. Corresponden a las casillas sobre fondo amarillo. RESTO DE CAMPOS: De no cumplimentarse, no serán considerados en la valoración de la oferta. Hay campos desplegables que validan los datos introducidos, NO debe hacerse "copiar y pegar" de datos, ya que el formato de los datos debe validarse.
A3: Número lote
A4: Lote: Localidad (Provincia) - Pruebas diagnósticas | B4: =IFERROR(VLOOKUP(B3,Criterios!B22:N35,2,FALSE),"")
A5: Razón social
A6: CIF
A7: Domicilio social
A8: Localidad | C8: Provincia
A9: Representación de la empresa
A10: Nombre y apellidos del representante de la empresa
A11: DNI del representante de la empresa
A12: =IF(B11<>"",CONCATENATE("Don/Dña. ",B10, ", con DNI nº ",B11,", en nombre propio/en representación de la empresa ",B5,", con domicilio social en ",B7," y con CIF nº ",B6,", declara que adscribirá a la ejecución del servicio los siguientes centros y equipos:"),"")
A13: Datos del centro
A14: Nombre del centro asistencial
A15: Dirección asistencial
A16: Localidad | C16: Provincia | D16: =IFERROR(VLOOKUP(B3,Criterios!B22:N35,13,FALSE),"Elija nº de lote") -> Elija nº de lote
A17: Teléfono | C17: Fax
A18: Horario de citación
A19: Horario de realización de pruebas
A20: Correo electrónico a efectos de notificaciones
A21: Página web
A22: Personas de contacto (citación, incidencias, aspectos administrativos,…)
A23: Nombre y apellidos
A24: Correo electrónico a efectos de notificaciones
A25: Teléfono
A26: Interlocutor médico
A27: Nombre y apellidos
A28: Correo electrónico a efectos de notificaciones
A29: Teléfono
... A36: OBLIGATORIO
A37: EQUIPAMIENTO | B37: Disponibilidad | C37: Marca y modelo | D37: Características específicas | F37: Puntuación máxima | G37: Puntuación obt. Caract.
A38: Tomografía axial computarizada (TAC) | F38: 15 | G38: =IFERROR(IF($B38="Si",VLOOKUP($D38,Criterios!$N$13:$O$14,2,FALSE),0),0) -> 0
A39: Ecógrafo | F39: 5 | G39: =IFERROR(IF($B39="Si",VLOOKUP($D39,Criterios!$N$17:$O$18,2,FALSE),0),0) -> 0
A40: Electromiógrafo
A41: UNIDADES ASISTENCIALES | B41: Disponibilidad
A42: Radiodiagnóstico (U.88)
A43: Neurología (U.17)
A44: Neurofisiología (U.18)
A46: VALORABLE
A47: EQUIPAMIENTO | B47: Disponibilidad | C47: Marca y modelo | D47: Características específicas | F47: Puntuación máxima | G47: Puntuación obtenida
...

Sheet LOTE (ECO)
A1: SERVICIO DE PRUEBAS DIAGNÓSTICAS PARA FRATERNIDAD-MUPRESPA EN LA COMUNIDAD AUTÓNOMA DE CASTILLA Y LEÓN LOTE ECOGRAFÍA
A2: IMPORTES OFERTADOS: A cumplimentar para TODOS LOS SERVICIOS OFERTADOS, tanto obligatorios como valorables. SERVICIOS OBLIGATORIOS: De no cumplimentarse, la OFERTA SERÁ EXCLUIDA. Corresponden a las casillas sobre fondo amarillo. RESTO DE CAMPOS: De no cumplimentarse, no serán considerados en la valoración de la oferta. Hay campos desplegables que validan los datos introducidos, NO debe hacerse "copiar y pegar" de datos, ya que el formato de los datos debe validarse.
A3: Número lote
A4: Lote: Localidad (Provincia) - Pruebas diagnósticas | B4: =IFERROR(VLOOKUP(B3,Criterios!B22:N35,2,FALSE),"")
A5: Razón social
A6: CIF
A7: Domicilio social
A8: Localidad | C8: Provincia
A9: Representación de la empresa
A10: Nombre y apellidos del representante de la empresa
A11: DNI del representante de la empresa
A12: =IF(B11<>"",CONCATENATE("Don/Dña. ",B10, ", con DNI nº ",B11,", en nombre propio/en representación de la empresa ",B5,", con domicilio social en ",B7," y con CIF nº ",B6,", declara que adscribirá a la ejecución del servicio los siguientes centros y equipos:"),"")
A13: Datos del centro
A14: Nombre del centro asistencial
A15: Dirección asistencial
A16: Localidad | C16: Provincia | D16: =IFERROR(VLOOKUP(B3,Criterios!B22:N35,13,FALSE),"Elija nº de lote") -> Elija nº de lote
A17: Teléfono | C17: Fax
A18: Horario de citación
A19: Horario de realización de pruebas
A20: Correo electrónico a efectos de notificaciones
A21: Página web
A22: Personas de contacto (citación, incidencias, aspectos administrativos,…)
A23: Nombre y apellidos
A24: Correo electrónico a efectos de notificaciones
A25: Teléfono
A26: Interlocutor médico
A27: Nombre y apellidos
A28: Correo electrónico a efectos de notificaciones
A29: Teléfono
... A36: OBLIGATORIO
A37: EQUIPAMIENTO | B37: Disponibilidad | C37: Marca y modelo | D37: Características específicas | F37: Puntuación máxima | G37: Puntuación obt. Caract.
A38: Tomografía axial computarizada (TAC) | G38: =IFERROR(IF($B38="Si",VLOOKUP($D38,Criterios!$N$13:$O$14,2,FALSE),0),0) -> 0
A39: Ecógrafo | F39: 13 | G39: =IFERROR(IF($B39="Si",VLOOKUP($D39,Criterios!$N$17:$O$18,2,FALSE),0),0) -> 0
A40: Electromiógrafo
A41: UNIDADES ASISTENCIALES | B41: Disponibilidad
A42: Radiodiagnóstico (U.88)
A43: Neurología (U.17)
A44: Neurofisiología (U.18)
A46: VALORABLE
A47: EQUIPAMIENTO | B47: Disponibilidad | C47: Marca y modelo | D47: Características específicas | F47: Puntuación máxima | G47: Puntuación obtenida
...

Sheet LOTES  (EMG)
A1: SERVICIO DE PRUEBAS DIAGNÓSTICAS PARA FRATERNIDAD-MUPRESPA EN LA COMUNIDAD AUTÓNOMA DE CASTILLA Y LEÓN LOTES ELECTROMIOGRAFÍA
A2: IMPORTES OFERTADOS: A cumplimentar para TODOS LOS SERVICIOS OFERTADOS, tanto obligatorios como valorables. SERVICIOS OBLIGATORIOS: De no cumplimentarse, la OFERTA SERÁ EXCLUIDA. Corresponden a las casillas sobre fondo amarillo. RESTO DE CAMPOS: De no cumplimentarse, no serán considerados en la valoración de la oferta. Hay campos desplegables que validan los datos introducidos, NO debe hacerse "copiar y pegar" de datos, ya que el formato de los datos debe validarse.
A3: Número lote
A4: Lote: Localidad (Provincia) - Pruebas diagnósticas | B4: =IFERROR(VLOOKUP(B3,Criterios!B22:N35,2,FALSE),"")
A5: Razón social
A6: CIF
A7: Domicilio social
A8: Localidad | C8: Provincia
A9: Representación de la empresa
A10: Nombre y apellidos del representante de la empresa
A11: DNI del representante de la empresa
A12: =IF(B11<>"",CONCATENATE("Don/Dña. ",B10, ", con DNI nº ",B11,", en nombre propio/en representación de la empresa ",B5,", con domicilio social en ",B7," y con CIF nº ",B6,", declara que adscribirá a la ejecución del servicio los siguientes centros y equipos:"),"")
A13: Datos del centro
A14: Nombre del centro asistencial
A15: Dirección asistencial
A16: Localidad | C16: Provincia | D16: =IFERROR(VLOOKUP(B3,Criterios!B22:N35,13,FALSE),"Elija nº de lote") -> Elija nº de lote
A17: Teléfono | C17: Fax
A18: Horario de citación
A19: Horario de realización de pruebas
A20: Correo electrónico a efectos de notificaciones
A21: Página web
A22: Personas de contacto (citación, incidencias, aspectos administrativos,…)
A23: Nombre y apellidos
A24: Correo electrónico a efectos de notificaciones
A25: Teléfono
A26: Interlocutor médico
A27: Nombre y apellidos
A28: Correo electrónico a efectos de notificaciones
A29: Teléfono
... A36: OBLIGATORIO
A37: EQUIPAMIENTO | B37: Disponibilidad | C37: Marca y modelo | D37: Características específicas | F37: Puntuación máxima | G37: Puntuación obt. Caract.
A38: Tomografía axial computarizada (TAC) | G38: =IFERROR(IF($B38="Si",VLOOKUP($D38,Criterios!$N$13:$O$14,2,FALSE),0),0) -> 0
A39: Ecógrafo | G39: =IFERROR(IF($B39="Si",VLOOKUP($D39,Criterios!$N$17:$O$18,2,FALSE),0),0) -> 0
A40: Electromiógrafo
A41: UNIDADES ASISTENCIALES | B41: Disponibilidad
A42: Radiodiagnóstico (U.88)
A43: Neurología (U.17)
A44: Neurofisiología (U.18)
A46: VALORABLE
A47: EQUIPAMIENTO | B47: Disponibilidad | C47: Marca y modelo | D47: Características específicas | F47: Puntuación máxima | G47: Puntuación obtenida
...

Sheet Criterios
B1: Centros adicionales | E1: Nº habitaciones | H1: Ecodoppler | K1: Horario consulta TAC y ECO | N1: Horario consulta ECO | Q1: SMS | T1: Teleconsulta | X1: Cód. provincia | Y1: Provincia
B2: No | C2: 0 | E2: No | F2: 0 | H2: No | I2: 0 | K2: No | L2: 0 | N2: No | O2: 0 | Q2: No | R2: 0 | T2: Criterio | U2: puntos | X2: 1 | Y2: ALAVA
B3: Si | C3: 1 | E3: De 1 a 2 habitaciones adicionales | F3: 3 | H3: Si | I3: 1 | K3: 1 hora diaria adicional | L3: 1 | N3: 1 hora diaria adicional | O3: 4 | Q3: Si | R3: 1 | T3: No | U3: 0 | X3: 2 | Y3: ALBACETE
E4: De 3 a 4 habitaciones adicionales | F4: 4.5 | K4: 2 horas diarias adicionales | L4: 2 | N4: 2 horas diarias adicionales | O4: 6 | T4: Si | U4: 5 | X4: 3 | Y4: ALICANTE
E5: Más de 4 habitaciones adicionales | F5: 6 | H5: RM/TAC | K5: 3 o más horas diarias adicionales | L5: 3 | N5: 3 o más horas diarias adicionales | O5: 9 | X5: 4 | Y5: ALMERIA
H6: No | I6: 0 | X6: 5 | Y6: AVILA
B7: RX (L4,6,8,10,12 Y 14) | E7: Nº quirófanos | H7: Si | I7: 2.5 | T7: Plataforma | X7: 6 | Y7: BADAJOZ
B8: No | C8: 0 | E8: No | F8: 0 | T8: Criterio | U8: puntos | X8: 7 | Y8: ILLES BALEARS
B9: Convencional | C9: 2 | E9: 1 quirófano adicional | F9: 1 | T9: No | U9: 0 | X9: 8 | Y9: BARCELONA
B10: Digital | C10: 5 | E10: 2 o más quirófanos adicionales | F10: 2 | H10: Unidades asistenciales | T10: Si | U10: 4 | X10: 9 | Y10: BURGOS
H11: No | I11: 0 | X11: 10 | Y11: CACERES
B12: RX (L1) | E12: Salas Rhb | H12: Si | I12: 1 | K12: TAC (L4,6,8,10,12 Y 14) | N12: TAC (L1) | Q12: TAC (resto lotes) | T12: Reducción tiempos | X12: 11 | Y12: CADIZ
B13: No | C13: 0 | E13: No | F13: 0 | K13: 16 cortes | L13: 0 | N13: 16 cortes | O13: 0 | Q13: 16 cortes | R13: 0 | T13: Criterio | U13: puntos | X13: 12 | Y13: CASTELLON
B14: Convencional | C14: 2 | E14: 1 sala adicional | F14: 1 | K14: superior a 16 cortes | L14: 5 | N14: superior a 16 cortes | O14: 15 | Q14: superior a 16 cortes | R14: 5 | T14: No | U14: 0 | X14: 13 | Y14: CIUDAD REAL
B15: Digital | C15: 5 | E15: 2 salas adicionales | F15: 2 | T15: Reducción en 24 horas | U15: 2 | X15: 14 | Y15: CORDOBA
E16: 3 o más salas adicionales | F16: 3 | K16: ECO (L4,6,8,10,12 Y 14) | N16: ECO (L2) | Q16: ECO (resto lotes) | T16: Reducción en 48 horas | U16: 5 | X16: 15 | Y16: CORUÑA
B17: RX (L2) | E17: RX (L3,5,7,9,11 y 13) | K17: 10 Megahercios | L17: 0 | N17: 10 Megahercios | O17: 0 | Q17: 10 Megahercios | R17: 0 | X17: 16 | Y17: CUENCA
B18: No | C18: 0 | E18: No | F18: 0 | K18: superior a 10 Megahercios | L18: 5 | N18: superior a 10 Megahercios | O18: 13 | Q18: superior a 10 Megahercios | R18: 5 | X18: 17 | Y18: GIRONA
B19: Convencional | C19: 2 | E19: Convencional | F19: 2 | X19: 18 | Y19: GRANADA
B20: Digital | C20: 5 | E20: Digital | F20: 5 | X20: 19 | Y20: GUADALAJARA
B21: Lote | C21: Nombre | D21: TAC | E21: ECO | F21: EMG | G21: DOPPLER | H21: RX INFORMADA | I21: RX SIN INFORMAR | J21: GAMMA | K21: ENG | L21: P. EVOCADOS | N21: Provincia | X21: 20 | Y21: GIPUZKOA
B22: 1 | C22: Burgos - TAC | D22: 109 | G22: 90 | H22: 30 | I22: 15 | J22: 250 | K22: 120 | L22: 150 | N22: Burgos | X22: 21 | Y22: HUELVA
B23: 2 | C23: Burgos - Ecografía | E23: 55 | G23: 90 | H23: 30 | I23: 15 | J23: 250 | K23: 120 | L23: 150 | N23: Burgos | X23: 22 | Y23: HUESCA
B24: 3 | C24: Burgos - EMG | F24: 123 | G24: 90 | H24: 30 | I24: 15 | J24: 250 | K24: 120 | L24: 150 | N24: Burgos | X24: 23 | Y24: JAEN
B25: 5 | C25: León - EMG | F25: 127 | G25: 90 | H25: 30 | I25: 15 | J25: 250 | K25: 120 | L25: 150 | N25: León | X25: 24 | Y25: LEON
B26: 7 | C26: Ponferrada - EMG | F26: 97 | G26: 90 | H26: 30 | I26: 15 | J26: 250 | K26: 120 | L26: 150 | N26: León | X26: 25 | Y26: LLEIDA
B27: 9 | C27: Salamanca - EMG | F27: 106 | G27: 90 | H27: 30 | I27: 15 | J27: 250 | K27: 120 | L27: 150 | N27: Salamanca | X27: 26 | Y27: LA RIOJA
B28: 11 | C28: Segovia - EMG | F28: 88 | G28: 90 | H28: 30 | I28: 15 | J28: 250 | K28: 120 | L28: 150 | N28: Segovia | X28: 27 | Y28: LUGO
B29: 13 | C29: Valladolid - EMG | F29: 108 | G29: 90 | H29: 30 | I29: 15 | J29: 250 | K29: 120 | L29: 150 | N29: Valladolid | X29: 28 | Y29: MADRID
B30: 4 | C30: León -- TAC y Ecografía | D30: 154 | E30: 55 | G30: 127 | H30: 30 | I30: 15 | J30: 250 | K30: 120 | L30: 150 | N30: León | X30: 29 | Y30: MALAGA
B31: 6 | C31: Ponferrada - TAC y Ecografía | D31: 107 | E31: 48 | G31: 90 | H31: 30 | I31: 15 | J31: 250 | K31: 120 | L31: 150 | N31: Léon | X31: 30 | Y31: MURCIA
B32: 8 | C32: Salamanca - TAC y Ecografía | D32: 105 | E32: 28 | G32: 90 | H32: 30 | I32: 15 | J32: 250 | K32: 120 | L32: 150 | N32: Salamanca | X32: 31 | Y32: NAVARRA
B33: 10 | C33: Segovia - TAC y Ecografía | D33: 117 | E33: 63 | G33: 90 | H33: 30 | I33: 15 | J33: 250 | K33: 120 | L33: 150 | N33: Segovia | X33: 32 | Y33: OURENSE
B34: 12 | C34: Valladolid - TAC y Ecografía | D34: 110 | E34: 50 | G34: 90 | H34: 30 | I34: 15 | J34: 250 | K34: 120 | L34: 150 | N34: Valladolid | X34: 33 | Y34: ASTURIAS
B35: 14 | C35: Zamora - TAC y Ecografía | D35: 111 | E35: 72 | G35: 127 | H35: 55 | I35: 40 | J35: 250 | K35: 120 | L35: 150 | N35: Zamora | X35: 34 | Y35: PALENCIA
X36: 35 | Y36: LAS PALMAS
X37: 36 | Y37: PONTEVEDRA
X38: 37 | Y38: SALAMANCA
X39: 38 | Y39: S.C.DE TENERIFE
X40: 39 | Y40: CANTABRIA
...
